Workbook
Name ADDRESS: Master!#REF!
Name CC: Master!$M:$M
Name CD: Master!#REF!
Name CITY: Master!#REF!
Name CLIENT: Master!$A:$A
Name CONTACT_2: Master!$AC:$AC
Name COUNTY: Master!#REF!
Name EQUIP: Master!$B:$B
Name INSTALL: Master!#REF!
Name LICENSE: Master!#REF!
Name NAME: Master!$P:$P
Name PHONE: Master!$Q:$Q
Name PHONE_2: Master!$AD:$AD
Name REC: Master!#REF!
Name REM: Master!#REF!
Name STATE: Master!$X:$X
Name TERMS: Master!#REF!
Name VERS: Master!#REF!
Name ZIP: Master!$Y:$Y

Sheet New Client
B2: #VALUE! | J2: Invoice No:
C4: 101 Glacier Point, Suite B | J4: Date:
C5: San Rafael, Ca 94901 | J5: TERMS:
C6: 415-451-4861 | E6: admin@performancepos.com | J6: Ordered by:
J7: Rep:
A9: ************************************************ | C9: ************************************ | F9: INVOICE | J9: *******************************
B11: Bill To | I11: Deliver To
B12: Client:
B13: c/o
B14: Address:
B15: City:
B16: Phone:
B17: Email:
C19: Products:
B20: Qty: | E20: Description: | J20: Unit Price | K20: Total
K21: =B21*J21 -> 0
K22: =B22*J22 -> 0
K23: =B23*J23 -> 0
K24: =B24*J24 -> 0
K25: =B25*J25 -> 0
K26: =B26*J26 -> 0
K27: =B27*J27 -> 0
I28: Taxable Subtotal: | K28: =SUM(K21:K27) -> 0
I29: Shipping
I30: Sales Tax | K30: =K28*J30 -> 0
C31: Services:
B32: Unit | E32: Description: | J32: Rate
K33: =J33*B33 -> 0
K34: =B34*J34 -> 0
K35: =B35*J35 -> 0
K36: =B36*J36 -> 0
K37: =B37*J37 -> 0
K38: =B38*J38 -> 0
J39: travel
C41: Payment Details
J42: TOTAL: | K42: =SUM(K28:K39) -> 0
J44: office use only:
C48: I agree to the above charges and to pay this invoice according to the stated terms
C50: Client Signature
D52: This is your invoice. Kindly Pay from this invoice

Sheet Invoice
J2: Invoice No: | K2: 12315805
C4: 101 Glacier Point, Suite B | J4: Date: | K4: 46022
C5: San Rafael, Ca 94901 | J5: TERMS: | K5: Net30
C6: 415-451-4861 | E6: admin@performancepos.com | J6: Ordered by:
J7: Rep: | K7: Antonio Hudnall
A8: ************************************************ | C8: ************************************ | F8: INVOICE | J8: *******************************
B9: Bill To | I9: Deliver To
B10: Client: | C10: El Quetzal Deli | I10: =C10 -> El Quetzal Deli
B11: c/o | C11: =LOOKUP(C10,Master!A:A,Master!AT:AT) -> 0
B12: Address: | C12: =LOOKUP(C10,Master!A:A,Master!AU:AU) -> 136 Bellam Boulevard | I12: =LOOKUP(C10,Master!A:A,Master!T:T) -> 136 Bellam Boulevard
B13: City: | C13: =LOOKUP(C10,Master!A:A,Master!AW:AW) -> San Rafael | E13: =LOOKUP(C10,Master!A:A,Master!AX:AX) -> Ca | F13: =LOOKUP(C10,Master!A:A,Master!AY:AY) -> 94901 | I13: =LOOKUP(C10,Master!A:A,Master!U:U) -> San Rafael | J13: =LOOKUP(C10,Master!A:A,Master!V:V) -> Ca | K13: =LOOKUP(C10,Master!A:A,Master!W:W) -> 94901
B14: Phone: | C14: =LOOKUP(C10,Master!A:A,Master!AZ:AZ) -> 415-259-7333 | I14: =LOOKUP(C10,Master!A:A,Master!O:O) -> 415-654-6312
B15: Email:
C17: Products:
B18: Qty: | E18: Description: | J18: Unit Price | K18: Total
K20: =B20*J20 -> 0
K21: =B21*J21 -> 0
K23: =B23*J23 -> 0
K24: =B24*J24 -> 0
K25: =B25*J25 -> 0
K26: =B26*J26 -> 0
I27: Taxable Subtotal: | K27: =SUM(K19:K26) -> 0
B28: =LOOKUP(C10,Master!A:A,Master!S:S) -> SR | I28: Shipping
I29: Sales Tax | J29: =LOOKUP(C10,Master!A:A,Master!Q:Q) -> 0.095 | K29: =K27*J29 -> 0
C30: Services:
B31: Unit | E31: Description: | J31: Rate
K32: =J32*B32 -> 0
K34: =B34*J34 -> 0
K35: =B35*J35 -> 0
K36: =B36*J36 -> 0
K37: =B37*J37 -> 0
J38: travel
C40: Payment Details
J41: TOTAL: | K41: =SUM(K27:K38) -> 0
J43: office use only:
C47: I agree to the above charges and to pay this invoice according to the stated terms
C49: Client Signature
D51: This is your invoice. Kindly Pay from this invoice

Sheet Master
A1: 46022 | B1: SYSTEM | E1: HELP DESK | H1: HW MAINT | K1: REVENUE TRACKING | N1: PRIMARY CONTACT | Q1: TAX% | R1: Tax % | S1: Tax Dist | T1: STORE ADDRESS | X1: Ops Email | Y1: Billing Email | Z1: Other Email | AA1: CONTACT #2 | AC1: CONTACT #3 | AE1: CONTACT #4 | AG1: CONTACT #5 | AI1: FAX | AK1: website | AL1: Paper #1 | AM1: Paper #2 | AN1: Paper #3 | AO1: Ribbon #1 | AP1: Ribbon #2 | AQ1: Label/Other | AR1: Other | AT1: Bill To Name | AU1: Street | AW1: City | AX1: St | AY1: Zip | AZ1: Phone
B2: type | C2: AM | D2: WS | E2: y/n ? | G2: $$ | H2: y/n ? | I2: exp | J2: $$ | K2: LAST SUPPLY?? | M2: LAST T&M ?? | N2: Name | O2: Phone | P2: Cell | T2: STREET | U2: CITY | V2: ST | W2: ZIP | AA2: Name | AB2: Phone | AC2: Name | AD2: Phone | AE2: Name | AF2: Phone | AG2: Name | AH2: Phone | AI2: Store | AJ2: Corp or A/P | AL2: Supply Info | AT2: Billing Info
A3: 16th Street Taco | B3: SUPPLY ONLY | C3: AH | E3: NO | H3: NO | M3: 44532 | N3: Eduardo Jaurez | O3: 415-725-0715 | Q3: 0.08625 | S3: SF | T3: 980 16th Street | U3: San Francisco | V3: Ca | W3: 94107 | AU3: 980 16th Street | AW3: San Francisco | AX3: Ca | AY3: 94107 | AZ3: 415-725-0715
A4: 2 Star Market | B4: CASIO | C4: LG | D4: Qt-6600 | E4: NO | H4: NO | M4: 43927 | N4: Ali | O4: 510-531-3576 | Q4: 0.1025 | S4: ALA | T4: 2020 MacArthur Blvd | U4: Oakland | V4: Ca | W4: 94602 | AU4: 2020 MacArthur Blvd | AW4: Oakland | AX4: Ca | AY4: 94602 | AZ4: 510-531-3576
A5: 22nd & Irving Market | B5: SCALE | C5: RA | D5: LP-1000 | E5: NO | H5: NO | K5: 45356 | M5: 44180 | N5: Chris | O5: 415-681-5212 | Q5: 0.08625 | S5: SF | T5: 2101 Irving Street | U5: San Francisco | V5: Ca | W5: 94122 | AQ5: 1493 | AU5: 2101 Irving Street | AW5: San Francisco | AX5: Ca | AY5: 94122 | AZ5: 415-681-5212
A6: 26 Mix | B6: ECR | C6: AH | D6: Sam4s ER945 raised | E6: NO | H6: NO | K6: 44358 | M6: 44449 | N6: William Mayorga | O6: 415-826-7378 | P6: 510-734-5931 | Q6: 0.08625 | R6: 0.0875 | S6: SF | T6: 3024 Mission Street | U6: San Francisco | V6: Ca | W6: 94110 | AU6: 3024 Mission Street | AW6: San Francisco | AX6: Ca | AY6: 94110 | AZ6: 415-826-7378
A7: 3 Star Food & Liquor | B7: CASIO | C7: LG | D7: Casio TE7000 | E7: NO | H7: NO | M7: 43026 | N7: Mandeep | O7: 510-340-1366 | Q7: 0.0975 | R7: 0.085 | S7: Concord | T7: 1140 Meadow Lane | U7: Concord | V7: Ca | W7: 94520 | AA7: Dependu | AU7: 1140 Meadow Lane | AW7: Concord | AX7: Ca | AY7: 94520 | AZ7: 510-340-1366
A8: 420 Smoke Palace **c.o.d. prepay** | B8: ECR | C8: AH | D8: Sam4s SAP-630 | E8: NO | F8: *COD/PREPAY ONLY** | H8: NO | I8: *COD/PREPAY ONLY** | K8: 43878 | M8: 44568 | N8: Abassi | O8: 408-880-4200 | Q8: 0.09375 | S8: SanJose | T8: 396 S. Bascom Avenue | U8: San Jose | V8: Ca | W8: 95128 | AL8: 54-230 | AU8: 396 S. Bacom Avenue | AW8: San Jose | AX8: Ca | AY8: 95128 | AZ8: 408-880-4200
A9: 5th Street Steakhouse | B9: SUPPLY ONLY | C9: AH | E9: NO | H9: NO | K9: 45968 | N9: Traci | O9: 530-891-6328 | Q9: 0.0925 | R9: 0.075 | S9: BUTTE | T9: 345 W. 5th Street | U9: Chico | V9: Ca | W9: 95928 | X9: wearschico@yahoo.com | Y9: wearschico@yahoo.com | AA9: Angela | AI9: 530-891-8339 | AL9: 54-230 | AM9: 13305 | AN9: 15741 | AO9: 62245 | AP9: 62235 | AU9: 345 W. 5th Street | AW9: Chico | AX9: Ca | AY9: 95928 | AZ9: 530-891-6328
A10: 65th Street Market | B10: ECR | C10: AH | D10: Sam4s ER260 | E10: NO | H10: NO | K10: 45881 | M10: 44249 | N10: Murshed Adbul | O10: 510-655-6838 | Q10: 0.105 | S10: Emery | T10: 6444 San Pablo Ave | U10: Emeryville | V10: Ca | W10: 94608 | AL10: 15157 | AU10: 6444 San Pablo Ave | AW10: Emeryville | AX10: Ca | AY10: 94608 | AZ10: 510-655-6838
A11: 76 Auto Care Service | B11: SUPPLY ONLY | C11: AH | E11: NO | H11: NO | K11: 43544 | N11: Babu | O11: 510-530-5605 | Q11: 0.1025 | S11: ALA | T11: 4500 Park Blvd | U11: Oakland | V11: Ca | W11: 94602 | AL11: 54-230 | AM11: 15153 | AU11: 4500 Park Blvd | AW11: Oakland | AX11: Ca | AY11: 94602 | AZ11: 510-530-5605
A12: 88 Sushi & Ramen | B12: SUPPLY ONLY | C12: AH | E12: 7 X 24 | F12: SpotOn | H12: NO | K12: 45197 | N12: J. Decastro | O12: 650-948-8388 | Q12: 0.0913 | S12: SC | T12: 530 Showers Drive. #4 | U12: Mountain View | V12: Ca | W12: 94040 | AL12: 15-741 | AU12: 530 Showers Drive, #4 | AW12: Mountain View | AX12: Ca | AY12: 94040 | AZ12: 650-948-8388
A13: 9th Street Market | B13: ECR | C13: AH | D13: Sam4s ER945 raised | E13: NO | H13: NO | K13: 44188 | M13: 44188 | N13: Nav Singh | O13: 707-542-5903 | P13: 559-260-5848 cell | Q13: 0.1 | S13: S.Rosa | T13: 766 Wilson Street | U13: Santa Rosa | V13: Ca | W13: 95401 | X13: mail4navsingh.nps@gmail.com | Y13: mail4navsingh.nps@gmail.com | Z13: mail4navsingh.nps@gmail.com | AL13: 15157 | AU13: 766 Wilson Street | AW13: Santa Rosa | AX13: Ca | AY13: 95401 | AZ13: 707-542-5903
A14: a Mano | B14: SUPPLY ONLY | C14: AH | E14: NO | H14: NO | K14: 44950 | M14: 44573 | N14: Rodrigo | O14: 415-506-7401 | P14: 415-271-3947 | Q14: 0.08625 | S14: SF | T14: 450 Hayes Street | U14: San Francisco | V14: Ca | W14: 94102 | X14: info@amanosf.com | Y14: iberdougo@backofthehouseinc.com | Z14: rodrigo@backofthehouseinc.com | AI14: 415-506-7401 | AL14: 54-230 | AM14: 13305 | AN14: CC235 | AO14: 62245 | AU14: 450 Hayes St | AW14: San Francisco | AX14: Ca | AY14: 94102 | AZ14: 415-881-7020
A15: A Sweet Affair - California | B15: SpotOn | C15: RA | E15: NO | H15: NO | M15: 43859 | N15: Terry Babcock | O15: 925-943-2253 | P15: 925-785-5931 | Q15: 0.0925 | R15: 0.085 | S15: CC | T15: 1991 N California Blvd | U15: Walnut Creek | V15: Ca | W15: 94598 | X15: asweetaffairbakery@usa.com | Y15: idreamofaruba@gmail.com | Z15: idreamofaruba@gmail.com | AA15: Sarah Torres -> | AB15: 925-395-1695 | AC15: EMAIL IDREAM | AU15: 1991 N California Blvd | AW15: Walnut Creek | AX15: Ca | AY15: 94598 | AZ15: 925-785-5931
A16: A Sweet Affair - Ygnacio | B16: SpotOn | C16: RA | E16: 7 X 24 | F16: SpotOn | M16: 44372 | N16: Terry Babcock | O16: 925-944-1910 | Q16: 0.0925 | R16: 0.085 | S16: CC | T16: 1815 Ygnacio Valley Road Ste F | U16: Walnut Creek | V16: Ca | W16: 94598 | X16: bakerhot1@aol.com | Y16: idreamofaruba@gmail.com | Z16: idreamofaruba@gmail.com | AA16: Terry-owner | AB16: 925-785-5931 | AI16: 925-947-6000 | AU16: 1815 Ygnacio Valley Road Ste F | AW16: Walnut Creek | AX16: Ca | AY16: 94598 | AZ16: 925-944-1910
A17: A&W - San Rafael | B17: BRINK | C17: MB | E17: M-F | F17: 45519 | G17: 49 | H17: NO | K17: 43747 | M17: 45762 | N17: David | O17: 415-479-9652 | P17: .; | Q17: 0.0925 | S17: SR | T17: 3741 Redwood Highway | U17: San Rafael | V17: Ca | W17: 94903 | X17: bigbromberger@gmail.com | Y17: brombergerville@hotmail.com | AL17: 15303 | AU17: 3741 Redwood Highway | AW17: San Rafael | AX17: Ca | AY17: 94903 | AZ17: 415-479-9652
A18: Ace Wasabi | B18: SUPPLY ONLY | C18: AH | K18: 44798 | N18: Ken Lowe | O18: 415-567-4903 | P18: 415-819-8477 | Q18: 0.08625 | R18: 0.0875 | S18: SF | T18: 3339 Steiner Street | U18: San Francisco | V18: Ca | W18: 94123 | X18: klowe1414@yahoo.com | Y18: klowe1234@gmail.com | AA18: vicas | AB18: 415-850-7530 | AI18: 415-749-1873 | AL18: 54-230 | AM18: 13305 | AO18: 67240 | AU18: 3339 Steiner Street | AV18: 3339 STEINER STREET | AW18: San Francisco | AX18: Ca | AY18: 94123 | AZ18: 415-576-4903
A19: Achilles by the Sea | B19: SPOT ON | C19: AH | E19: 7 X 24 | F19: SpotOn | K19: 45527 | N19: Diaa Atali | O19: 650-476-6663 | P19: 650-476-6663 | Q19: 0.0925 | S19: S.Cruz | T19: 1404 Soquel Ave | U19: Santa Cruz | V19: Ca | W19: 95062 | X19: achillessantaclara@gmail.com | Y19: achillessantaclara@gmail.com | Z19: achillessantaclara@gmail.com | AL19: 54-230 | AM19: 13305 | AO19: 62245 | AU19: 1404 Soquel Ave | AW19: Santa Cruz | AX19: Ca | AY19: 95062 | AZ19: 650-476-6663
A20: Acre Restaurant | B20: Spot On | C20: DK | E20: Spot On | H20: NO | K20: 45999 | M20: 45309 | N20: Dirk/Kirsten | Q20: 0.1025 | S20: ALA | T20: 5655 College Ave | U20: Oakland | V20: Ca | W20: 94618 | X20: kirsten@acre-restaurant.com | Y20: kirsten@acre-restaurant.com | Z20: kirsten@acre-restaurant.com | AL20: 54230 | AM20: 13305 | AN20: cc235 | AO20: 62245 | AQ20: 15741 | AU20: 5655 College Ave | AW20: Oakland | AX20: Ca | AY20: 94618
A21: Agave - Healdsburg | B21: SUPPLY ONLY | C21: AH | E21: NO | H21: NO | M21: 44403 | N21: Octavio Diaz | O21: 707-433-2411 | Q21: 0.0975 | S21: Heald | T21: 1063 Vine St | U21: Healdsburg | V21: Ca | W21: 95448 | X21: daisy@merlobiz.com | Y21: mail@merlobiz.com | Z21: tishia@merlobiz.com | AU21: 1063 Vine St | AW21: Healdsburg | AX21: Ca | AY21: 95448 | AZ21: 707-433-2411
A22: Aguachiles El Tamarindo | B22: NCC | C22: LG | E22: NO | H22: NO | M22: 45110 | N22: Edgar | O22: 510-500-7552 | P22: 510-393-2242 cell | Q22: 0.1025 | S22: ALA | T22: 3053 International Blvd | U22: Oakland | V22: Ca | W22: 94601 | Y22: eg333366@gmail.com | AU22: 3053 International Blvd | AW22: Oakland | AX22: Ca | AY22: 94601 | AZ22: 510-500-7552
A23: Alana's - Burlingame | B23: NCC | C23: LG | E23: 7 X 24 | F23: 45505 | G23: 49 | H23: DEPOT | I23: 45505 | J23: 39 | K23: 45887 | M23: 45855 | N23: Francesca | O23: 650-348-0417 | P23: 650-799-9230 | Q23: 0.09625 | R23: 0.09 | S23: Burl | T23: 1408 Burlingame Avenue | U23: Burlingame | V23: Ca | W23: 94010 | X23: info@alanascafe.com | Y23: francesca@alanascafe.com | AA23: Teresa | AC23: Tim | AD23: 650-703-9981 | AL23: 54-230 | AN23: CC235 | AO23: 62245 | AU23: =PROPER(AV23) -> 1408 Burlingame Avenue | AV23: 1408 BURLINGAME AVENUE | AW23: Burlingame | AX23: Ca | AY23: 94010 | AZ23: 650-348-0417
A24: Alegria's | B24: SUPPLY ONLY | C24: AH | E24: NO | H24: NO | K24: 43077 | M24: 43668 | N24: Angelynne | O24: 415-929-8888 | Q24: 0.08625 | R24: 0.0875 | S24: SF | T24: 2018 Lombard Street | U24: San Francisco | V24: Ca | W24: 94123 | X24: info@alegraissf.com | AA24: Arman | AM24: CC235 | AO24: 62245 | AU24: =PROPER(AV24) -> 2018 Lombard Street | AV24: 2018 LOMBARD STREET | AW24: San Francisco | AX24: Ca | AY24: 94123 | AZ24: 415-929-8888
A25: Alejandro's Taqueria - Fairfield | B25: ECR | C25: AH | D25: Sam ER940 flat | E25: NO | H25: NO | K25: 45215 | M25: 42929 | N25: Lety | O25: 707-429-2155 | Q25: 0.08375 | S25: SOL | T25: 936 Texas Street | U25: Fairfield | V25: Ca | W25: 94533 | AL25: 15157 | AM25: 44150 | AO25: 67655 | AU25: 936 Texas Street | AW25: Fairfield | AX25: Ca | AY25: 94533 | AZ25: 707-429-2155
A26: Alejandro's Taqueria - Sacramento | B26: ECR | C26: AH | D26: Sam ER940 flat | E26: NO | H26: NO | M26: 43581 | N26: Luis | O26: 916-459-0924 | Q26: 0.0875 | S26: SacCity | T26: 911 K Street | U26: Sacramento | V26: Ca | W26: 95814 | X26: lbarr@sbcglobal.net | Z26: lbarr@sbcglobal.net | AL26: 15157 | AU26: 911 K Street | AW26: Sacramento | AX26: Ca | AY26: 95814 | AZ26: 916-459-0924
A27: All Star Donut | B27: ECR | C27: AH | D27: SAM 260 | E27: NO | H27: NO | M27: 44858 | N27: Sem | O27: 510-525-7289 | Q27: 0.1025 | R27: 0.095 | S27: El Cerr | T27: 3070 El Cerrito Plaza | U27: El Cerrito | V27: Ca | W27: 94530 | AU27: 3070 El Cerrito Plaza | AW27: El Cerrito | AX27: Ca | AY27: 94530 | AZ27: 510-525-7289
A28: Alley & Vine | B28: SUPPLY ONLY | C28: AH | E28: NO | H28: NO | K28: 45257 | N28: Ricardo | O28: 510-227-5006 | Q28: 0.1075 | S28: ALA | T28: 1332 Park St Suite D | U28: Alameda | V28: Ca | W28: 94501 | AL28: 54-230 | AM28: 15741 | AN28: CC235 | AU28: 1332 Park St Suite D | AW28: Alameda | AX28: Ca | AY28: 94501 | AZ28: 510-227-5006
A29: Alotta's Deli & Catering | B29: NCC | C29: RA | E29: *** COD/ Prepay only ONLY ** | H29: NO | M29: 45721 | N29: Mike Mansch | O29: 650-967-0299 | P29: 408-807-0575 | Q29: 0.0925 | S29: LosAltos | T29: 2249 Grant Road | U29: Los Altos | V29: Ca | W29: 94024 | X29: alottasdeli@aol.com | Y29: alottasdeli@aol.com | Z29: alottasdeli@aol.com | AU29: 2249 Grant Road | AW29: Los Altos | AX29: Ca | AY29: 94024 | AZ29: 650-967-0299
A30: Amakara | B30: SUPPLY ONLY | C30: AH | E30: NO | H30: NO | K30: 46003 | M30: 43032 | N30: Myly | O30: 925-803-8485 | P30: 925-992-9819 | Q30: 0.1025 | R30: 0.095 | S30: ALA | T30: 7568 Dublin Blvd | U30: Dublin | V30: Ca | W30: 94568 | X30: amakaracompany@gmail.com | AA30: Eddie (owner) | AB30: 209-601-8923 | AC30: Tae Oh | AD30: 408-981-6142 | AL30: 54-230 | AM30: 13305 | AN30: CC235 | AO30: 62245 | AU30: 7568 Dublin Blvd | AV30: 7222 REGIONAL STREET | AW30: Dublin | AX30: Ca | AY30: 94568 | AZ30: 925-803-8485
A31: Amal's Deli | B31: NCC | C31: RA | E31: NO | H31: NO | M31: 44776 | N31: Rana | O31: 415-227-3797 | Q31: 0.08625 | S31: SF | T31: 1416 Haight St | U31: San Francisco | V31: Ca | W31: 94117 | AU31: 1416 Haight St | AW31: San Francisco | AX31: Ca | AY31: 94117 | AZ31: 415-227-3797
A32: American Bull | B32: NCC | C32: RA | E32: NO | H32: NO | K32: 43363 | M32: 43955 | N32: Liz Jones | O32: 650-652-4908 | P32: 650-504-3947 | Q32: 0.09625 | R32: 0.09 | S32: Burl | T32: 1819 El Camino Real | U32: Burlingame | V32: Ca | W32: 94010 | X32: theamericanbullbarandgrill@gmail.com | AA32: Daniel (Liz's son) | AB32: 650-504-3945 | AI32: 650-652-9825 | AL32: 54-230 | AM32: 13305 | AO32: 62245 | AU32: =PROPER(AV32) -> 1819 El Camino Real | AV32: 1819 EL CAMINO REAL | AW32: Burlingame | AX32: Ca | AY32: 94010 | AZ32: 650-652-4908
A33: Anaheim White House | B33: SUPPLY ONLY | C33: AH | E33: NO | H33: NO | K33: 45939 | N33: Sylvano | O33: 714-772-1381 | Q33: 0.0775 | S33: OC | T33: 887 S. Anaheim Blvd | U33: Anaheim | V33: Ca | W33: 92805 | Y33: katie@anaheimwhitehouse.com | AL33: 54-230 | AM33: CC235 | AO33: 62245 | AU33: 887 S. Anaheim Blvd | AW33: Anaheim | AX33: Ca | AY33: 92805 | AZ33: 714-772-1381
A34: Ananda Fuara | B34: SUPPLY ONLY | C34: AH | E34: NO | H34: NO | K34: 44760 | M34: 43649 | N34: Golapendu | O34: 415-621-1994 | P34: 415-812-1327 | Q34: 0.08625 | R34: 0.0875 | S34: SF | T34: 1298 Market Street | U34: San Francisco | V34: Ca | W34: 94102 | AL34: 54230 | AM34: 13305 | AO34: 67240 | AU34: 1298 Market Street | AW34: San Francisco | AX34: Ca | AY34: 94102 | AZ34: 415-621-1994
A35: Anderson Valley Brewing | B35: SUPPLY ONLY | C35: AH | E35: NO | H35: NO | K35: 43675 | N35: Rebecca | O35: 707-895-2337 | Q35: 0.07875 | R35: 0.0762 | S35: Mendo | T35: 17700 Highway 253 | U35: Boonville | V35: Ca | W35: 95415 | X35: reception@avbc.com | Y35: rpaez@avbc.com | AA35: Vicky ( A/P) | AI35: 707-895-2353 | AL35: 54-230 | AU35: P.O. Box 505 | AV35: 17700 HIGHWAY 253 | AW35: Boonville | AX35: Ca | AY35: 95415 | AZ35: 707-895-2337
A36: Andi's Market | B36: NCC | C36: LG | D36: 570-2 | E36: NO | H36: NO | K36: 45979 | M36: 44897 | N36: Morris | O36: 415-648-4656 | P36: 559-960-2025 cell | Q36: 0.08625 | R36: 0.0875 | S36: SF | T36: 820 Cortland Avenue | U36: San Francisco | V36: Ca | W36: 94110 | X36: mlmanji@gmail.com | Y36: mlmanji@gmail.com | Z36: mlmanji@gmail.com | AL36: 54-230 | AM36: 15185 | AQ36: GoDex /roll | AU36: 820 Cortland Avenue | AW36: San Francisco | AX36: Ca | AY36: 94110 | AZ36: 415-648-4656
A37: Andy & Yu's | B37: SpotOn | C37: AH | E37: 7 X 24 | F37: SpotOn | H37: NO | K37: 45454 | M37: 45434 | N37: Nicole | O37: 925-750-8888 | Q37: 0.1025 | S37: Pleas | T37: 348 St.Mary Street | U37: Pleasanton | V37: Ca | W37: 94566 | AU37: 348 St. Mary Street | AW37: Pleasanton | AX37: Ca | AY37: 94566 | AZ37: 925-750-8888
A38: Andy's Local Market | B38: SUPPLY ONLY | C38: AH | E38: NO | H38: NO | K38: 45453 | N38: Paige/Robert | O38: 415-456-5730 | Q38: 0.0925 | S38: SR | T38: 75 Loch Lomond Drive | U38: San Rafael | V38: Ca | W38: 94901 | X38: bernie@andyslocalmarket.com | AL38: 54-230 | AN38: CC235 | AO38: 62245 | AP38: 18-333 | AU38: 75 Loch Lomond Drive | AW38: San Rafael | AX38: Ca | AY38: 94901 | AZ38: 415-456-5730
A39: Angela's Kitchen | B39: SUPPLY ONLY | C39: AH | E39: NO | H39: NO | K39: 44594 | N39: Saboor | O39: 510-263-8788 | P39: 510-333-4874 | Q39: 0.1075 | R39: 0.095 | S39: ALA | T39: 1640 Park Street | U39: Alameda | V39: Ca | W39: 94501 | X39: zboor58@gmail.com | Y39: zboor58@gmail.com | AA39: Lisa | AI39: 510-864-0803 | AL39: 54-230 | AM39: 18333 | AO39: 67240 | AU39: 1640 Park Street | AW39: Alameda | AX39: Ca | AY39: 94501 | AZ39: 510-522-5822
A40: Antigua Cocina | B40: ECR | C40: AH | D40: SAM4S ER260 | E40: NO | H40: NO | M40: 44400 | N40: Marvin | O40: 415-879-6670 | Q40: 0.0925 | S40: Novato | T40: 1559 S. Novato Blvd, Suite J | U40: Novato | V40: Ca | W40: 94945 | AU40: 1559 S. Novato Blvd | AW40: Novato | AX40: Ca | AY40: 94945 | AZ40: 415-879-6670
...

Sheet TAX RATES 2025
A1: Effective Sales and Use Tax Rates | E1: 45748
A3: Location | B3: Rate | C3: County | D3: Type | E3: Notes
A5: Adelanto | B5: 0.0775 | C5: San Bernardino | D5: City
A6: Agoura Hills | B6: 0.095 | C6: Los Angeles | D6: City
A7: Alameda | B7: 0.1075 | C7: Alameda | D7: City
A8: Alameda County | B8: 0.1025 | C8: Alameda | D8: County
A9: Albany | B9: 0.1075 | C9: Alameda | D9: City
A10: Alhambra | B10: 0.105 | C10: Los Angeles | D10: City
A11: Aliso Viejo | B11: 0.0775 | C11: Orange | D11: City
A12: Alpine County | B12: 0.0725 | C12: Alpine | D12: County
A13: Alturas | B13: 0.0725 | C13: Modoc | D13: City
A14: Amador City | B14: 0.0775 | C14: Amador | D14: City
A15: Amador County | B15: 0.0775 | C15: Amador | D15: County
A16: American Canyon | B16: 0.0775 | C16: Napa | D16: City
... A120: Del Mar | B120: 0.0875 | C120: San Diego | D120: City
A121: Del Norte County | B121: 0.0725 | C121: Del Norte | D121: County | E121: This county tax rate applies to areas that are within the boundaries of any incorporated city within the county of Del Norte
A122: Del Norte County Unincorporated Area | B122: 0.0825 | C122: Del Norte | D122: County | E122: This county tax rate applies to areas that are not within the boundaries of any incorporated city within the county of Del Norte
A123: Del Rey Oaks | B123: 0.0925 | C123: Monterey | D123: City
A124: Delano | B124: 0.0825 | C124: Kern | D124: City
A125: Desert Hot Springs | B125: 0.0875 | C125: Riverside | D125: City
A126: Diamond Bar | B126: 0.095 | C126: Los Angeles | D126: City
A127: Dinuba | B127: 0.085 | C127: Tulare | D127: City
A128: Dixon | B128: 0.08375 | C128: Solano | D128: City
A129: Dorris | B129: 0.0725 | C129: Siskiyou | D129: City
A130: Dos Palos | B130: 0.0775 | C130: Merced | D130: City
A131: Downey | B131: 0.105 | C131: Los Angeles | D131: City
A132: Duarte | B132: 0.105 | C132: Los Angeles | D132: City
A133: Dublin | B133: 0.1025 | C133: Alameda | D133: City
A134: Dunsmuir | B134: 0.0775 | C134: Siskiyou | D134: City
... A218: Kerman | B218: 0.08975 | C218: Fresno | D218: City
A219: Kern County | B219: 0.0725 | C219: Kern | D219: County | E219: This county tax rate applies to areas that are within the boundaries of any incorporated city within the county of Kern
A220: Kern County Unincorporated Area | B220: 0.0825 | C220: Kern | D220: County | E220: This county tax rate applies to areas that are not within the boundaries of any incorporated city within the county of Kern
A221: King City | B221: 0.0875 | C221: Monterey | D221: City
A222: Kings County | B222: 0.0725 | C222: Kings | D222: County
A223: Kingsburg | B223: 0.08975 | C223: Fresno | D223: City
A224: La Canada Flintridge | B224: 0.105 | C224: Los Angeles | D224: City
A225: La Habra | B225: 0.0875 | C225: Orange | D225: City
A226: La Habra Heights | B226: 0.095 | C226: Los Angeles | D226: City
A227: La Mesa | B227: 0.085 | C227: San Diego | D227: City
A228: La Mirada | B228: 0.095 | C228: Los Angeles | D228: City
...

Sheet Sell Items
C1: PPOS product list
C5: Item# | D5: Description | J5: Price | K5: Ext
B7: PAPER
B8: 1 | C8: # 54-230 | D8: Epson Thermal | F8: 3 1/8 x 230' | H8: 0668 | I8: 50 rolls | J8: 99 | K8: =B8*J8 -> 99
B9: 1 | C9: # 13-305 | D9: Epson Impact | F9: 3" one ply x 165 | I9: 50 rolls | J9: 59 | K9: =B9*J9 -> 59
B10: 1 | C10: # CC-235 | D10: 3" TWO ply | F10: Epson TMU-220 | H10: 0047 | I10: 50 rolls | J10: 76 | K10: =B10*J10 -> 76
B11: 1 | C11: # 15-741 | D11: CC Machine | F11: 2.25" x 74 feet | H11: 5061 | I11: 50 rolls | J11: 39 | K11: =B11*J11 -> 39
B13: 1 | C13: # 11-094 | D13: one ply paper | F13: 3" one ply x 194 | I13: 50 rolls | J13: 59 | K13: =B13*J13 -> 59
B14: 1 | C14: # 12-100 | D14: one ply paper | F14: 2 1/4" x 150 feet | H14: 0510 | I14: 100 rolls | J14: 84 | K14: =B14*J14 -> 84
B15: 1 | C15: # 13-305C | D15: one ply paper | F15: 3" one ply canary | H15: 2015 | I15: 50 rolls | J15: 77 | K15: =B15*J15 -> 77
B16: 1 | C16: # 13-305G | D16: one ply paper | F16: 3" one ply green | H16: 2016 | I16: 50 rolls | J16: 72 | K16: =B16*J16 -> 72
B17: 1 | C17: # 15-044 | D17: thermal paper | F17: 44mm x 230 feet | I17: 50 rolls | J17: 76 | K17: =B17*J17 -> 76
B18: 1 | C18: # 15-157 | D18: 2 1/4 x 230'thermal | F18: Cash Reg- Thermal | H18: 2983 | I18: 50 rolls | J18: 82 | K18: =B18*J18 -> 82
B19: 1 | C19: # 15-160 | D19: 2 1/4 x 60' thermal | F19: Verifone Thermal | I19: 50 rolls | J19: 39 | K19: =B19*J19 -> 39
B20: 1 | C20: # 15-185 | D20: 2 1/4 x 85' thermal | F20: Verifone Thermal | H20: 0549 | I20: 50 rolls | J20: 39 | K20: =B20*J20 -> 39
B21: 1 | C21: # 15-040 | D21: Poynt CC station | F21: 2.25" x 16 feet | H21: 5040 | I21: 50 rolls | J21: 29 | K21: =B21*J21 -> 29
B22: 1 | C22: # 15-303 | D22: thermal paper | F22: 2.25" x 42 feet | H22: 2981 | I22: 48 rolls | J22: 39 | K22: =B22*J22 -> 39
B23: 1 | C23: # 18-333 | D23: three ply paper | F23: 3" w/c/p | I23: 50 rolls | J23: 89 | K23: =B23*J23 -> 89
B24: 1 | C24: # 46-015 | D24: thermal paper | F24: 3" x 230 feet | I24: 50 rolls | J24: 103 | K24: =B24*J24 -> 103
B25: 1 | C25: # 46-175 | D25: thermal paper | F25: 3 1/8 Heavy | I25: 50 rolls | J25: 124 | K25: =B25*J25 -> 124
B26: 1 | C26: # 54-170 | D26: thermal paper | F26: 3 1/8" x 110 feet | I26: 50 rolls | J26: 62 | K26: =B26*J26 -> 62
B27: 1 | C27: # 54-273 | D27: thermal paper | F27: 3 1/8 x 273' | H27: 0566 | I27: 50 rolls | J27: 116 | K27: =B27*J27 -> 116
B28: 1 | C28: # 64-437 | D28: 44mm one ply paper | F28: 44mm x 150 ft | I28: 100 rolls | J28: 73 | K28: =B28*J28 -> 73
B29: 1 | C29: #15-350 | D29: 2 1/4" x 50' thermal | F29: 2.25" x 50 ft | H29: 8056 | I29: 50 rolls | J29: 22.95 | K29: =B29*J29 -> 22.95
B30: 1 | C30: # 15-999 | D30: POS paper rolls | F30: Other | J30: 59 | K30: =B30*J30 -> 59
B32: INK
B33: 1 | C33: # 62245 | D33: black/red ribbons | F33: EPSON TM-220 series | I33: Per Dozen | J33: 42 | K33: =B33*J33 -> 42
B34: 1 | C34: # 67240 | D34: black/red ribbons | F34: STAR SP700 series | I34: Per Dozen | J34: 52 | K34: =B34*J34 -> 52
B36: 1 | C36: # ERC-38 | D36: Epson black/red | F36: Epson TM-U2220 | I36: Per Dozen | J36: 59 | K36: =B36*J36 -> 59
B37: 1 | C37: # 67655 | D37: purple ribbons | F37: Tec 1450/1650 | I37: Per Dozen | J37: 49 | K37: =B37*J37 -> 49
B38: 1 | C38: # 67215 | D38: purple ribbons | F38: Tec RKP300 | I38: Per Dozen | J38: 39 | K38: =B38*J38 -> 39
B39: 1 | C39: # 62285 | D39: purple ribbons | F39: Tec MA1350 | I39: Per Dozen | J39: 39 | K39: =B39*J39 -> 39
B40: 1 | C40: # 62240 | D40: purple ribbons | F40: Epson 30/34/38 | I40: Per Dozen | J40: 52 | K40: 52
B41: 1 | C41: # 62235 | D41: black ribbons | F41: Epson 30/34/38 | I41: Per Dozen | J41: 52 | K41: =B41*J41 -> 52
B42: 1 | C42: # 62225 | D42: purple ribbons | F42: Tec DRS207 | I42: Per Dozen | J42: 39 | K42: =B42*J42 -> 39
B44: 1 | C44: # 62-199 | D44: POS ribbon/ink | F44: Other | I44: Per Dozen | J44: 39 | K44: =B44*J44 -> 39
B45: 1 | C45: # 62-198 | D45: POS ribbon/ink | F45: Other | I45: each | J45: 7.5 | K45: =B45*J45 -> 7.5
B46: 1 | C46: # 62-197 | D46: Office Printer Toner | I46: each | J46: 55 | K46: =B46*J46 -> 55
B47: 1 | C47: # 62-196 | D47: Office Printer Drum | I47: each | J47: 45 | K47: =B47*J47 -> 45
B50: LABELS
...

Sheet EMPLOYEES
A1: Performance POS 415-451-4861 100-A Pelican Way, San Rafael CA 94901
A2: Toll-Free Support: 888-411-3375 support@performancepos.com
A4: Employee | C4: Ext | D4: Desk | E4: Cell | F4: Email
A6: Antonio Hudnall | B6: AH | C6: 112 | D6: 415-720-8345 | E6: 415-532-6834 | F6: antonio@performancepos.com
A7: Austen | E7: 515-337-3309
A8: Mo | E8: 650-242-6487
A9: Rick Villasin | E9: 415-203-9112
A10: Denny Deyerle | B10: DD | C10: 110 | D10: 415-755-3512 | E10: 209-801-2674 | F10: denny@performancepos.com
A11: Doug Kelly | B11: DK | C11: 102 | D11: 415-521-0979 | E11: 415-432-0630 | F11: dougkelly@performancepos.com
A12: Eltjon Lala | B12: EL | C12: 108 | D12: 415-755-0408 | E12: 978-608-3975 | F12: eltjon@performancepos.com
A13: Ernesto | E13: 415-706-5775
A14: Jose Santos | B14: JS | C14: 109 | D14: 415-755-0111 | E14: 415-747-2564 | F14: josesantos@performancepos.com
A15: Josue | E15: 510-480-5415
A16: Lowell Galang | B16: LG | C16: 106 | D16: 415-755-5910 | E16: 650-278-2997 | F16: lgalang@performancepos.com
A17: Milton Bland | B17: MB | C17: 107 | D17: 415-755-0337 | E17: 415-747-0039 | F17: milton@performancepos.com
A18: Rich Alden | B18: RA | C18: 104 | D18: 415-521-0776 | E18: 415-747-0038 | F18: richalden@performancepos.com
A19: Rob Freaney | B19: RF | C19: 101 | D19: 415-521-0548 | E19: 415-747-2568 | F19: robfreaney@performancepos.com
A21: Outside Tech Resources
A23: Pete Pizzino | B23: PP | D23: 510-506-6316 | F23: cashreg@sbcglobal.net
A24: POS & ECR
A25: NCC & RHQ | D25: 866-944-5164 | F25: nccusa.com & nccusa.com/rhq
A26: Posera Maitre'd | D26: 888-404-2662 | F26: distributors.maitredpos.com
A27: Casio | D27: 800-633-5586 | F27: casio.com
A28: Credit Cards
A29: Datacap | D29: 215-997-8989 | F29: datacapsystems.com
A30: Mercury Vantiv | D30: 800-846-4472 | F30: techsupport@mercurypay.com
A31: Sterling | D31: 800-591-6098 | F31: sterlingpayment.com
